Workbook

Sheet Índice
B1: 📚 INDICE DE RECOMENDACIONES - 2º CUATRI 2026 - LA CÁMPORA 📚
A2: Accedé a los links o ingresá directamente en las distintas hojas para ver toda la información ¡Éxitos!
A3: 1 | B3: Teoría del Estado
A4: 2 | B4: Teoría General del Derecho
A5: 3 | B5: Elementos del Derecho Civil
A6: 4 | B6: Derechos Humanos y Garantías
A7: 5 | B7: Elementos de Análisis Económico y Financiero
A8: 6 | B8: Elementos del Derecho Constitucional
A9: 7 | B9: Obligaciones Civiles y Comerciales
A10: 8 | B10: Contratos Civiles y Comerciales
A11: 9 | B11: Elementos del Derecho Penal y Procesal Penal
A12: 10 | B12: Elementos del Derecho Comercial
A13: 11 | B13: Elementos de Derechos Reales
A14: 12 | B14: Elementos de Derecho Procesal Civil
... A22: 20 | B22: Comisiones Recomendadas por la Red de Profesoras de la Facultad de Derecho
A23: Los comentarios e información de estas hojas fueron relevadas en las aulas y grupos de Whatsapp de estudiantes, esperamos que te sirvan para anotarte. Si cursaste en alguna comisión de la que no tengamos data o haya información incorrecta, no dudes en contarnos por MD en el Instagram @lacamporaderechouba.

Sheet TGD
A1: 📚 TEORÍA GENERAL DEL DERECHO - 2º CUATRI 2026 - LA CÁMPORA 📚
A2: N° | B2: COMISIÓN | C2: DÍAS | D2: MODALIDAD | E2: HORARIO | F2: NIVEL | G2: EXAMEN | H2: TOMA LISTA | I2: TOMA TPS | J2: COMENTARIO | K2: POSTURA POLITICA
A3: 6010 | B3: ALONSO-BOICO | C3: MA-VI | D3: PRESENCIAL | E3: 07:00-08:30 | F3: MEDIO | G3: ESCRITO | H3: NO | I3: NO | J3: Toman lo dado en clase, los parciales son de 3 preguntas a desarrollar. | K3: TECNICA
A4: 6073 | B4: ALONSO.-RANIERI D. | C4: LU-JU | D4: PRESENCIAL | E4: 07:00-08:30 | F4: MEDIO | G4: ESCRITO | H4: SI | I4: SI | J4: Es exigente pero no tanto, los profes son copados y las clases se prestan al debate, toman un tp que ayuda a levantar nota. Es importante estar al día con el material, los parciales se basan más en la teoria que en lo dado en clase. IMPORTANTE: En el primer cuatrimestre esta comisión no fue abierta por no llegar al mínimo de inscriptos que exige la Facultad. | K4: TECNICA
A5: 6050 | B5: ROSENKRANTZ-DIMITRIU | C5: LU-JU | D5: PRESENCIAL | E5: 07:00-08:30 | F5: MEDIO | G5: MIXTO | H5: SI | I5: NO | J5: Los profesores tiene buen trato con los estudiantes, no tienen ánimos de bochar y responden dudas sin problemas. Toman dos parciales, uno escrito a desarrollar y otro oral. IMPORTANTE: En el primer cuatrimestre esta comisión no fue abierta por no llegar al mínimo de inscriptos que exige la Facultad.
A6: 6000 | B6: ALEGRE-SEMINARIO LAURA | C6: MIE | D6: PRESENCIAL | E6: 07:00-10:00 | F6: ALTO | G6: ESCRITO | H6: SI | I6: NO | J6: Hay opiniones encontradas acerca del trato de los docentes con los estudiantes, poca llegada para responder y hacer llevadera la cursada que puede complicar la materia. // OTRA OPINIÓN: Buena comisión, se entiende todo y no tienen ánimos de bochar. Se aprende mucho y son exigentes
A7: 6011 | B7: ALONSO-BOICO | C7: MA-VI | D7: PRESENCIAL | E7: 08:30-10:00 | F7: MEDIO | G7: ESCRITO | H7: NO | I7: NO | J7: Toman lo dado en clase, los parciales son de 3 preguntas a desarrollar. Son Pro alumno | K7: TECNICA
A8: 6060 | B8: ALONSO-DUQUELSKY | C8: LU-JU | D8: PRESENCIAL | E8: 08:30-10:00 | F8: MEDIO | H8: NO | I8: SI | J8: Evalúan con 4tps (obligatorios) bastante sencillos y un tp final, cuenta la nota del último para el cierre de la materia. El profe es pro alumno, comprensivo y generoso con las notas. Las clases son muy divertidas y se analiza el derecho desde una perspectiva critica. | K8: APERTURA
A9: 6079 | B9: ALONSO.-RANIERI D. | C9: LU-JU | D9: PRESENCIAL | E9: 08:30-10:00 | F9: MEDIO | G9: ESCRITO | H9: SI | I9: SI | J9: * Es exigente pero no tanto, los profes son copados y las clases se prestan al debate, toman un tp que ayuda a levantar nota. Es importante estar al día con el material, los parciales se basan más en la teoria que en lo dado en clase. IMPORTANTE: En el primer cuatrimestre esta comisión no fue abierta por no llegar al mínimo de inscriptos que exige la Facultad.El 1er cuatri de 2026 fue abierta. | K9: CONSERVADORA
A10: 6031 | B10: MARTYNIUK-BARRERA L. | C10: LU-JU | D10: PRESENCIAL | E10: 08:30-10:00 | F10: MEDIO | G10: ESCRITO | H10: SI | J10: Buena cátedra, no tienen ánimos de bochar a nadie. Si bien no ponen notas altas los parciales no son dificiles (3 preguntas a desarrollar), la mayoría promociona. La profe tiene buena onda y la cursada es con perspectiva feminista, muy interesante.
A11: 6061 | B11: MARTYNIUK-HEFFES AGOS O.D. | C11: MA-VI | D11: PRESENCIAL | E11: 08:30-10:00 | F11: MEDIO | G11: MIXTO | H11: NO | I11: SI | J11: El profesor hace la clase llevadera. El primer parcial fue domiciliario y el segundo un trabajo en grupo a exponer.
A12: 6051 | B12: ROSENKRANTZ-ZULETA MARTÍN | C12: LU-JU | D12: PRESENCIAL | E12: 08:30-10:00 | F12: MEDIO | G12: ESCRITO | H12: SI | I12: NO | J12: Los profesores tiene buen trato con los estudiantes, no tienen ánimos de bochar y responden dudas sin problemas. Toman dos parciales, uno escrito a desarrollar y otro oral
A13: 6080 | B13: ZULETA-SCATAGLINI | C13: LU-JU | D13: PRESENCIAL | E13: 08:30-10:00 | F13: MEDIO | G13: ESCRITO | H13: SI | J13: Cada 15 días había un encuentro sincrónico con la profesora por Meet. Parciales a desarrollar, con casos actuales. Busca que los alumnos formulen respuestas completas en base a lo que opinan. | K13: APERTURA
A14: 6005 | B14: ALEGRE-RAMALLO | C14: LU-JU | D14: PRESENCIAL | E14: 10:00-11:30 | F14: MEDIO | G14: MIXTO | H14: SI | I14: NO | J14: Los profes explican muy bien y son pro alumno, super promocionable. Los parciales son choice con algunas preguntas a desarrollar. Toman lo dado en clase, y el cuatri pasado no tomaron tps pero si una exposición oral grupal, nada muy complicado.
A15: 6002 | B15: ALEGRE-SANTANATOGLIA | C15: LU-JU | D15: PRESENCIAL | E15: 10:00-11:30 | F15: MEDIO | G15: ESCRITO | H15: NO | I15: NO | J15: Buena cátedra, la profe explica bien y hay buena disposición del equipo docente. Toman dos parciales ambos a desarrollar.
A16: 6062 | B16: ALONSO-DUQUELSKY | C16: LU-JU | D16: PRESENCIAL | E16: 10:00-11:30 | F16: MEDIO | H16: NO | I16: SI | J16: Evaluan con 4tps (obligatorios) bastante sencillos y un tp final, cuenta la nota del ùltimo para el cierra de la materia. El profe es pro alumno, comprensivo y generoso con las notas. Las clases son muy divertidas y se analiza el derecho desde una perspectiva crìtica. | K16: APERTURA
A17: 6087 | B17: GAIDO - BIANCHI A. | C17: LU-JU | D17: PRESENCIAL | E17: 10:00-11:30 | F17: MEDIO | G17: MULTIPLECHOICE | H17: SI | I17: SI | J17: Toman lista, los parciales son dos multiplechoice y toman durante el cuatrimestre un TP para mantener la regularidad. IMPORTANTE: En el primer cuatrimestre esta comisión no fue abierta por no llegar al mínimo de inscriptos que exige la Facultad.
A18: 6033 | B18: MARTYNIUK-BARRERA L. | C18: LU-JU | D18: PRESENCIAL | E18: 10:00-11:30 | F18: ALTO | G18: ESCRITO | H18: SI | J18: La profe a veces no se da a entender bien, pero tienen buena predisposición para responder dudas. Toman dos parciales generalmente de 4 preguntas a desarrollar, llevando las lecturas al día y prestando atención en clase se aprueba. Cursada con perspectiva feminista.
A19: 6030 | B19: MARTYNIUK-IBARRA R. | C19: MA-VI | D19: PRESENCIAL | E19: 10:00-11:30 | F19: MEDIO | G19: ESCRITO | H19: NO | I19: NO | J19: Son principalmente dos profes. Respetan mucho el cronograma y cargan todo el material de la cursada en un drive. Toman dos parciales escritos sobre los textos vistos en clase (de dos preguntas, para desarrollar en una carilla cada una). Es una cátedra exigente pero ordenada, si se está al día con el material se aprueba con buena nota. Se promociona con 4 y se tienen que contestar mínimamente bien ambas preguntas. | K19: APERTURA
A20: 6055 | B20: ROSENKRANTZ-CALVO SOLER | C20: LU-JU | D20: PRESENCIAL | E20: 10:00-11:30 | F20: BAJO | G20: MULTIPLECHOICE | H20: SI | I20: SI | J20: Cátedra pro alumno, muy promocionable. Toman dos parciales múltiple choice y dos tps (no obligatorios) que sirven para levantar nota. | K20: TECNICA
A21: 6052 | B21: ROSENKRANTZ-CALVO SOLER | C21: MIE | D21: PRESENCIAL | E21: 10:00-13:00 | F21: BAJO | G21: MIXTO | H21: SI | I21: SI | J21: Hay TPs con notas. Los exámenes son escritos y multiplechoice. Los profes son copados y dan buenas clases
A22: 6088 | B22: GAIDO - BIANCHI A. | C22: LU-JU | D22: PRESENCIAL | E22: 11:30-13:00 | F22: MEDIO | G22: MULTIPLECHOICE | H22: SI | I22: SI | J22: Toman lista, los parciales son dos multiplechoice y toman durante el cuatrimestre un TP para mantener la regularidad
A23: 6063 | B23: MARTYNIUK-DEMCZUK | C23: LU-JU | D23: PRESENCIAL | E23: 11:30-13:00 | F23: MEDIO | G23: ESCRITO | H23: NO | I23: NO | J23: Cátedra pro alumno. La clase la da el profesor Nicolás Vainer, es un genio, explica muy bien y las veces que sea necesario, suben el material de lectura al campus, no hay tps y los parciales son escritos (antes de cada parcial hacen clase de repaso).
A24: 6032 | B24: MARTYNIUK-IBARRA R. | C24: MA-VI | D24: PRESENCIAL | E24: 11:30-13:00 | F24: MEDIO | G24: ESCRITO | H24: NO | I24: NO | J24: Son principalmente dos profes. Respetan mucho el cronograma y cargan todo el material de la cursada en un drive. Toman dos parciales escritos sobre los textos vistos en clase (de dos preguntas, para desarrollar en una carilla cada una). Es una cátedra exigente pero ordenada, si se está al día con el material se aprueba con buena nota. Se promociona con 4 y se tienen que contestar mínimamente bien ambas preguntas. | K24: APERTURA
A25: 6064 | B25: MARTYNIUK-DEMCZUK | C25: LU-JU | D25: PRESENCIAL | E25: 13:00:14:30 | F25: MEDIO | G25: ESCRITO | H25: NO | I25: NO | J25: Cátedra pro alumno. La clase la da el profesor Nicolás Vainer, es un genio, explica muy bien y las veces que sea necesario, suben el material de lectura al campus, no hay tps y los parciales son escritos (antes de cada parcial hacen clase de repaso).
A26: 6021 | B26: ALONSO-CAÑAL | C26: MA-VI | D26: VIRTUAL | E26: 14:00-15:30 | F26: MEDIO | G26: MIXTO | H26: SI | I26: SI | J26: Buen equipo docente, sin ánimos de bochar gente. La cursada mezcla filosofía y derecho, es importante participar en clases. El primer parcial suele ser choice y el segundo un coloquio.
A27: 6020 | B27: ALONSO-AGREDA M. | C27: LU-JU | D27: PRESENCIAL | E27: 14:00-15:30 | F27: MEDIO | G27: ESCRITO | H27: NO | I27: NO | J27: Càtedra pro alumno. Toman lo dado en clase (complementado con el material que es poco). La primera parte es filosofìa màs general con lìnea epistemològica. La segunda parte es filosofìa del derecho. Full positivista, evalùan "teorìa pura del derecho" de Kelsen. | K27: APERTURA
A28: 6007 | B28: ALEGRE ABAL FEDERICO | C28: LU-JU | D28: PRESENCIAL | E28: 15:30-17:00 | F28: ALTO | G28: ESCRITO | H28: NO | I28: NO | J28: Cátedra exigente, no toman lista pero hay que prestar mucha atención en clase porque toman muy puntillosamente lo que dan. Hay que trabajar muy bien los textos. Toman parciales a desarrollar con libro abierto
A29: 6004 | B29: ALEGRE-CHORNY E. | C29: LU-JU | D29: VIRTUAL | E29: 15:30-17:00 | F29: MEDIO | G29: MIXTO | H29: SI | J29: Recomendable. Cátedra con perspectiva de género, la cursada es llevadera y organizada, siguen mucho el cronograma. Hay bastante para leer y algunas clases se complementan con videos de YouTube de los profes. Evalúan tomando dos parciales choice con alguna pregunta a desarrollar y también toman una presentación oral. | K29: APERTURA
A30: 6024 | B30: ALONSO-CALO MAIZA | C30: MA-VI | D30: PRESENCIAL | E30: 15:30-17:00 | F30: MEDIO | G30: ESCRITO | H30: SI | J30: Cuesta agarrarle el ritmo a la cursada pero es promocionable. Toman dos parciales, el primero es escrito y el segundo oral un poco màs complicado.
A31: 6023 | B31: ALONSO-CAÑAL | C31: MA-VI | D31: PRESENCIAL | E31: 15:30-17:00 | F31: MEDIO | G31: MIXTO | H31: SI | I31: SI | J31: Muy buena càtedra, con un enfoque critico interesante. La cursada es bastante dinàmica y los profes son pro alumno. Toman un tp para mantener la regularidad y evalùan con un examen al final de la materia.
A32: 6041 | B32: RABBI B.-IRIBARNE S. | C32: LU-JU | D32: PRESENCIAL | E32: 15:30-17:00 | F32: MEDIO | G32: ESCRITO | H32: NO | I32: NO | J32: Buena cátedra, las clases son muy organizadas y el profe explica bien, para cada tema de la cursada hay un fallo que lo trata. Evalúan con dos parciales escritos no muy extensos.
A33: 6081 | B33: ZULETA-MARTINEZ G. | C33: LU-JU | D33: VIRTUAL | E33: 15:30-17:00 | F33: MEDIO | G33: ESCRITO | H33: SI | I33: NO | J33: Las clases se las dividen entre dos profesoras. Hay dos parciales escritos y toman lo dado en clase. | K33: APERTURA
A34: 6008 | B34: ALEGRE ABAL FEDERICO | C34: MIE | D34: VIRTUAL | E34: 15:30-18:30 | F34: MEDIO | G34: MIXTO | J34: Los parciales son mitad escrito a desarrollar, mitad choice, mete choices prácticos en la clase para control de lectura. Recomendable, muy buen docente
A35: 6022 | B35: ALONSO-DOLABJIAN D. | C35: MIE | D35: PRESENCIAL | E35: 15:30-18:30 | F35: MEDIO | G35: ESCRITO | H35: NO | I35: NO | J35: Cátedra pro alumno. Toman lo dado en clase (complementado con el material que es poco). La primera parte es filosofía más general con línea epistemológica. La segunda parte es filosofía del derecho. Full positivista, evalúan "teoría pura del derecho" de Kelsen. | K35: APERTURA
A36: 6056 | B36: BOHMER-BOHMER | C36: LU-JU | D36: PRESENCIAL | E36: 17:00-18:30 | F36: ALTO | G36: MIXTO | H36: SI | I36: NO | J36: Catedra exigente, intercala clases teorícas con prácticas, 1 examen escrito y 1 oral. Salis aprendiendo y se puede promocionar pero no te regalan nota
A37: 6053 | B37: BOHMER-MANTIÑAN | C37: LU-JU | D37: PRESENCIAL | E37: 17:00-18:30 | J37: Comisión nueva
A38: 6042 | B38: RABBI B.-IRIBARNE S. | C38: LU-JU | D38: PRESENCIAL | E38: 17:00-18:30 | F38: MEDIO | G38: ESCRITO | H38: NO | I38: NO | J38: Son 3 profes, explican bien y toman lo dado en clase. Hay que estar al día con los fallos y el manual, los parciales son de 3/4 preguntas no tan complejas a desarrollar. | K38: TECNICA
A39: 6082 | B39: ZULETA-REPETTO | C39: LU-JU | D39: PRESENCIAL | E39: 17:00-18:30 | F39: MEDIO | G39: ESCRITO | I39: SI | J39: La comisión es desordenada y hay opiniones encontradas sobre las explicaciones de los docentes. Toman más de un TP por cuatrimestre.
A40: 6083 | B40: ZULETA-SGRAZUTTI | C40: MA-VI | D40: PRESENCIAL | E40: 17:00-18:30 | F40: MEDIO | G40: ESCRITO | H40: NO | I40: SI | J40: Parciales domiciliarios a desarrollar. pro alumno, control de regularidad con TP. | K40: TECNICA
...

Sheet TDE
A1: 📚 TEORÍA DEL ESTADO - 2º CUATRI 2026 - LA CÁMPORA 📚
A2: N° | B2: COMISIÓN | C2: DÍAS | D2: MODALIDAD | E2: HORARIO | F2: NIVEL | G2: EXAMEN | H2: TOMA LISTA | I2: TOMA TPS | J2: COMENTARIO | K2: POSTURA
A3: 6218 | B3: BERCHOLC - BERCHOLC | C3: LU-JU | D3: PRESENCIAL | E3: 18:30 - 20:00HS | F3: MEDIO | G3: MIXTO | H3: SI | I3: SI | J3: Comisión sin ánimos de bochar. Tienen buena llegada con los estudiantes, no tienen problema en poner notas altas y si te falta nota podés rendir un TP para promocionar la materia.
A4: 6236 | B4: D AURIA-HEFFES AGOS O.D. | C4: MA-VI | D4: PRESENCIAL | E4: 07:00-08:30 | F4: MEDIO | G4: ESCRITO | H4: SI | I4: NO | J4: El profesor Omar Heffes es super recomendado por sus alumnos, da explicaciones con cada texto de la fecha, lleva el cronograma de clases al dia. Todo el material esta en el campus (bibliografia aportada por la catedra. | K4: APERTURA
A5: 6210 | B5: BERCHOLC-BARILE | C5: LU-JU | D5: VIRTUAL | E5: 08:30-10:00 | F5: MEDIO | G5: MIXTO | H5: SI | I5: NO | J5: Hay opiniones encontradas sobre esta comisión acerca de los tiempos para rendir los parciales. El primero fue escrito con solo 20 minutos para contestar
A6: 6211 | B6: BERCHOLC-BARRAZA | C6: MA-VI | D6: VIRTUAL | E6: 07:00-8:30 | F6: BAJO | G6: MIXTO | H6: NO | I6: SI | J6: ATENCIÓN: Cambió el adjunto. Última recomendación: los parciales son choice y a desarrollar. Envia textos para estudiar // No recomendada, los profesores son desorganizados, llegan tarde a los parciales y hacen TPs sobre conferencias a las que te hacen asistir que promedian con los parciales. | K6: APERTURA
A7: 6240 | B7: DE LUCA-CAMPIONE | C7: LU-JU | D7: PRESENCIAL | E7: 08:30-10:00 | F7: MEDIO | G7: ESCRITO | H7: NO | I7: SI | J7: Toma 3 o 4 preguntas a desarrollar. Manda videos explicativos. Pro alumno. | K7: APERTURA
A8: 6261 | B8: FEDERICI-GUMA CHRISTIAN | C8: MA-VI | D8: PRESENCIAL | E8: 08:30-10:00 | F8: MEDIO | G8: ESCRITO | H8: NO | I8: NO | J8: ATENCIÓN: Cambió el adjunto. Última recomendación: Se toma lo visto en clase, la mayoría promociona.
A9: 6260 | B9: FEDERICI-FLORIO | C9: LU-JU | D9: PRESENCIAL | E9: 08:30-10:00 | F9: MEDIO | G9: MIXTO | H9: NO | I9: NO | J9: La cursada puede ser desorganizada, toman multiple-choice relativamente fáciles y después orales los propios compañeros tenemos que poner nota,
A10: 6270 | B10: SCHERLIS-GABRIEL S. | C10: LU-JU | D10: PRESENCIAL | E10: 08:30-10:00 | F10: BAJO | G10: MULTIPLECHOICE | H10: SI | I10: NO | J10: Son 4 parciales, buen trato y sin ánimos de bochar.
A11: 6271 | B11: SCHERLIS-WADDELL J. | C11: MA-VI | D11: PRESENCIAL | E11: 08:30-10:00 | F11: BAJO | G11: ESCRITO | H11: NO | I11: NO | J11: solo da clase 1 docente, es cordial con los estudiantes, quiere que participan en clase. Tiene las clases diagramadas en el cronograma da 1 autor por clase (la clase no suele extenderse toda la hora de cursada) toma 2 parciales escritos y hay 1 recuperarorio por parcial que también es escrito, toma 3 preguntas por parcial y da varios temas. El segundo parcial es más complicado porque hay que desarrollar un autor que te da al azar | K11: TECNICA
A12: 6212 | B12: BERCHOLC-FAMA ADRIAN | C12: MI | D12: PRESENCIAL | E12: 08:30-11:30 | F12: BAJO | G12: MIXTO | H12: NO | I12: SI | J12: ATENCIÓN: Cambió el adjunto. Última recomendación: los parciales son choice y a desarrollar. Envia textos para estudiar // No recomendada, los profesores son desorganizados, llegan tarde a los parciales y hacen TPs sobre conferencias a las que te hacen asistir que promedian con los parciales. | K12: APERTURA
A13: 6221 | B13: CAO C.-ZAPPA MARÍA SOLEDAD | C13: MI | D13: PRESENCIAL | E13: 08:30-11:30 | H13: SI
A14: 6242 | B14: DE LUCA-CAMPIONE | C14: MI | D14: PRESENCIAL | E14: 08:30-11:30 | F14: MEDIO | G14: ESCRITO | H14: NO | I14: SI | J14: Toma 3 o 4 preguntas a desarrollar. Manda videos explicativos. Pro alumno. | K14: APERTURA
A15: 6219 | B15: CAO C-PIERPAULI RICARDO | C15: LU-JU | D15: PRESENCIAL | E15: 10:00-11:30 | F15: BAJO | G15: ESCRITO | H15: SI | I15: NO | J15: No tienen problemas en poner notas altas a la hora de corregir, mandan una guía de preguntas dos semanas antes de las que sacan después las consignas del parcial así que es súper promocionable. A considerar que te hacen comprar dos libros de profesor en su editorial y que son abiertamente conservadores y religiosos | K15: CONSERVADORA
A16: 6228 | B16: CAO-PIERPAULLI RICARDO | C16: LU-JU | D16: PRESENCIAL | E16: 10:00-11:30 | F16: BAJO | G16: ESCRITO | H16: SI | I16: NO | J16: No tienen problemas en poner notas altas a la hora de corregir, mandan una guía de preguntas dos semanas antes de las que sacan después las consignas del parcial así que es súper promocionable. A considerar que te hacen comprar dos libros de profesor en su editorial y que son abiertamente conservadores y religiosos | K16: CONSERVADORA
A17: 6230 | B17: D AURIA-VITA LETICIA | C17: MA-VI | D17: PRESENCIAL | E17: 10:00-11:30 | F17: ALTO | G17: MIXTO | H17: NO | I17: NO | J17: Amenas. Mandan bastante para leer pero no es condición necesaria para aprobar. Los temas centrales se ven en la clase y los textos sirven para reforzar si queres 10. Los profes explican bien y dan mucho lugar a que participen. La profe está en el conicet sabe mucho de divulgación.
A18: 6243 | B18: DE LUCA-BURSZTYN DEBORA | C18: MA-VI | D18: PRESENCIAL | E18: 10:00-11:30 | F18: MEDIO | G18: MULTIPLECHOICE | H18: SI | I18: NO | J18: Explican muy bien. Los parciales son 60 multiple choice y te dan 1 hora y media para completarlo. Toman lo visto en clase, el material lo suben al campus en un drive. | K18: TECNICA
A19: 6252 | B19: DE LUCA-VIDELA MONTILLA | C19: LU-JU | D19: VIRTUAL | E19: 10:00-11:30 | F19: MEDIO | G19: MULTIPLECHOICE | H19: SI | I19: NO | J19: Los profesores te dan el material para estudiar y las clases son llevaderas.
A20: 6262 | B20: FEDERICI-HALAMAN | C20: MA-VI | D20: PRESENCIAL | E20: 10:00-11:30 | F20: ALTO | G20: MIXTO | H20: SI | I20: SI | J20: Comisión exigente con el material, hay que llevarla muy al día para promocionarla. Toman dos parciales que suelen varias cuatrimestre tras cuatrimestre aunque saben tomar multiple-choice a justificar o TPs grupales como método de evaluación
A21: 6213 | B21: BERCHOLC-BARRAZA | C21: MI | D21: PRESENCIAL | E21: 10:00-13:00 | F21: MEDIO | G21: ESCRITO | H21: SI | I21: SI | J21: Es una cátedra organizada, siguen el cronograma y evaluan con parciales escritos (3 preguntas). Realiza excursiones. | K21: -
A22: 6272 | B22: SCHERLIS-AGUIRRE G. | C22: SA | D22: PRESENCIAL | E22: 10:00-13:00 | F22: MEDIO | G22: ESCRITO | H22: NO | I22: SI | J22: El profesor es organizado, los parciales son domiciliarios de una semana a la otra y se entregan resúmenes que el profesor puede ir eligiendo al azar. No tiene ánimos de bochar, es exigente en la corrección mas pone notas altas
A23: 6281 | B23: SCHERLIS-PERICOLA | C23: MI | D23: PRESENCIAL | E23: 10:00-13:00 | F23: MEDIO | G23: ESCRITO | H23: SI | I23: NO | J23: Toman dos parciales escritos con 3 preguntas a desarrollar. Comisión muy completa con buena llegada con los estudiantes; siguen al pie de la letra el cronograma de clases que mandan al comienzo de la cursada
A24: 6200 | B24: A DESIG.-DI GIOIA | C24: MA-VI | D24: PRESENCIAL | E24: 11:30-13:00
A25: 6231 | B25: D AURIA-VITA LETICIA | C25: MA-VI | D25: PRESENCIAL | E25: 11:30-13:00 | F25: MEDIO | G25: MIXTO | H25: NO | I25: NO | J25: Siguen el cronograma, son ordenados. Dan modelos de parciales para practicar. No toman TPs, los parciales son multiplechoice y a desarrollar.
A26: 6241 | B26: DE LUCA-BURSZTYN DEBORA | C26: MA-VI | D26: PRESENCIAL | E26: 11:30-13:00 | F26: MEDIO | G26: MULTIPLECHOICE | H26: SI | I26: NO | J26: Explican muy bien. Los parciales son 60 multiple choice y te dan 1 hora y media para completarlo. Toman lo visto en clase, el material lo suben al campus en un drive. | K26: TECNICA
A27: 6244 | B27: DE LUCA-FINOCCHIARO | C27: MA-VI | D27: PRESENCIAL | E27: 11:30-13:00 | F27: ALTO | G27: MIXTO | H27: SI | I27: NO | J27: Los parciales son escritos con recuperatorio y final orales. Contenido pesado, mucho para leer. Clases aburridas. | K27: CONSERVADORA
A28: 6263 | B28: FEDERICI-FLORIO | C28: MA-VI | D28: PRESENCIAL | E28: 11:30-13:00 | F28: BAJO | G28: MIXTO | H28: SI | I28: NO | J28: Dos parciales, el primero escrito y el segundo oral. Para los dos te da las preguntas de antemano. El parcial escrito son 4 preguntas y una a elección personal. Es muy difícil comunicarse con los docentes, tardan en contestar. Se usa el manual de Justo López que puede ser de difícil lectura por falta de acompañamiento didáctico en las clases
A29: 6273 | B29: SCHERLIS-GABRIEL S. | C29: LU-JU | D29: PRESENCIAL | E29: 11:30-13:00 | F29: BAJO | G29: MULTIPLECHOICE | H29: SI | I29: NO | J29: Son 4 parciales, buen trato y sin ánimos de bochar.
A30: 6274 | B30: SCHERLIS-LESCANO G. | C30: LU-JU | D30: PRESENCIAL | E30: 11:30-13:00 | F30: MEDIO | G30: ESCRITO | H30: NO | I30: SI | J30: Muy recomendada. Toman dos parciales escritos de 2 o 3 preguntas de temas vistos en clase sin ninguna sorpresa y un TP de regularidad. El profesor tiene buena llegada pero la ayudante es la mejor haciendo que las clases sean súper llevaderas; responden todas las dudas y no tienen ningún ánimo de bochar | K30: APERTURA
A31: 6275 | B31: SCHERLIS-LESCANO G. | C31: MA-VI | D31: PRESENCIAL | E31: 11:30-13:00 | F31: MEDIO | G31: ORAL | H31: SI | I31: NO | J31: Recomendada. Cátedra inclusiva y con perspectiva feminista, toman 2 orales de 5 minutos sin ánimos de bochar ni en los parciales ni en el recuperatorio. Recomendada | K31: APERTURA
A32: 6235 | B32: D AURIA-IBARRA | C32: MA-VI | D32: PRESENCIAL | E32: 14:00-15:30 | F32: MEDIO | G32: ESCRITO | H32: NO | I32: NO | J32: Muy recomendada. Los profesores tienen buen trato con los estudiantes con gran disposición para responder dudas y explicar siguiendo el cronograma. Cada clase se ve un texto diferente y la segunda mitad es con perspectiva nacional. Los parciales son dos con dos preguntas a desarrollar que ambas deben contestarse mínimamente bien (recuperatorio igual) y el final es oral. Se disfruta mucho, si bien no toman lista se recomienda ir por las clases. | K32: APERTURA
A33: 6245 | B33: DE LUCA-SCARRAMBERG JUAN MARTIN | C33: LU-JU | D33: PRESENCIAL | E33: 07:00 a 8:30 | F33: MEDIO | G33: ESCRITO | H33: NO | I33: NO | J33: No toma lista pero se recomienda ir a las clases ya que estudiando de los apuntes se puede promocionar. No tienen problema en poner notas altas y no tienen ningún ánimo de bochar. | K33: TECNICA
A34: 6282 | B34: SCHERLIS-WINER | C34: MI | D34: PRESENCIAL | E34: 14:00-17:00 | F34: MEDIO | G34: ORAL | H34: SI | I34: SI | J34: Toman un TP por semana conceptual para llevar la regularidad, pasan lista y toman dos exámenes. Al final de la cursada podés exponer un trabajo en clase de manera optativa
A35: 6234 | B35: D AURIA-BALERDI | C35: MA-VI | D35: PRESENCIAL | E35: 15:30-17:00 | F35: MEDIO | G35: ESCRITO | H35: SI | I35: NO | J35: El primer parcial escrito, dos preguntas a desarrollar. El segundo es domiciliario para entregarlo en una semana, te dan tres preguntas y elegís dos.
A36: 6232 | B36: D AURIA-DOTI A. | C36: LU-JU | D36: PRESENCIAL | E36: 15:30-17:00 | F36: MEDIO | G36: MIXTO | H36: SI | I36: NO | J36: Los profesores son muy buena onda, las clases son entretenidas y el material muy interesante. El primer parcial son preguntas a desarrollar y el segundo una monografía sobre una película. Notas altas, la mayoría promociona. Lo malo es que son muy desorganizados con el material y no siguen estrictamente el cronograma. También llegan tarde. | K36: TECNICA
A37: 6233 | B37: D AURIA-IBARRA | C37: MA-VI | D37: PRESENCIAL | E37: 15:30-17:00 | F37: MEDIO | G37: ESCRITO | H37: NO | I37: NO | J37: Muy recomendada. Los profesores tienen buen trato con los estudiantes con gran disposición para responder dudas y explicar siguiendo el cronograma. Cada clase se ve un texto diferente y la segunda mitad es con perspectiva nacional. Los parciales son dos con dos preguntas a desarrollar que ambas deben contestarse mínimamente bien (recuperatorio igual) y el final es oral. Se disfruta mucho, si bien no toman lista se recomienda ir por las clases. | K37: APERTURA
A38: 6264 | B38: FEDERICI-GALLARDO | C38: MA-VI | D38: PRESENCIAL | E38: 15:30-17:00 | F38: MEDIO | G38: MIXTO | H38: NO | I38: NO | J38: La modalidad de parciales se decide por votación, pueden ser orales o escritos. Preguntas a desarrollar, una sobre un fallo y otra la da el profesor la clase antes del parcial. En los parciales solamente se evalúan los textos , pero no se explican en clase. No se le da importancia a lo dado en clase la hora de evaluar. Es muy desorganizada. No se recomienda. | K38: CONSERVADORA
A39: 6276 | B39: SCHERLIS-PERICOLA M. | C39: LU-JU | D39: PRESENCIAL | E39: 15:30-17:00 | F39: ALTO | G39: MIXTO | H39: SI | I39: SI | J39: Las clases pueden ser aburridas y en los parciales, demorandose mucho para corregir, ponen notas bajas sin justificar por qué. Hay poco espacio para justificar ya que la modalidad es multiple-choice a justificar. | K39: TECNICA
A40: 6223 | B40: D AURIA-CABRERA M. | C40: MI | D40: PRESENCIAL | E40: 15:30-18:30 | F40: ALTO | G40: ESCRITO | H40: SI | I40: SI | J40: muy cerrado. mala dirección hacia los alumnos. si llegas tarde o algo, se enoja. | K40: CONSERVADORA
...

Sheet CIVIL
A1: 📚 ELEMENTOS DEL DERECHO CIVIL - 2º CUATRI 2026 - LA CÁMPORA 📚
A2: N° | B2: COMISIÓN | C2: DÍAS | D2: MODALIDAD | E2: HORARIO | F2: NIVEL | G2: EXAMEN | H2: TOMA LISTA | I2: TOMA TPS | J2: COMENTARIO | K2: POSTURA
A3: 6840 | B3: LAFERRIERE-MUÑIZ | C3: LU-JU | D3: PRESENCIAL | E3: 07:00-08:30 | F3: ALTO | G3: MIXTO | H3: SI | J3: Los profes explican bien y son bastante organizados. Evaluan con dos parciales que tienen una parte choice y otra desarrollar, son bastante específicos pero se aprueba.
A4: 6800 | B4: PERALTA MARISCAL-LOVECE G. | C4: MA-VI | D4: VIRTUAL | E4: 07:00-08:30 | F4: ALTO | G4: ESCRITO | H4: SI | I4: SI | J4: Recomiendo, catedra muy organizada y cumple con el cronograma. Las profes son lo más, explican bien, se aprende mucho. Los parciales son a desarrollar, nada rebuscados, pero son exigentes con las condiciones de evaluación | K4: TECNICA
A5: 6813 | B5: PERALTA MARISCAL-REY M. | C5: LU-JU | D5: PRESENCIAL | E5: 07:00-08:30 | F5: MEDIO | G5: ESCRITO | H5: SI | J5: Las profesras explican muybien. Nancy los días lunes (lleva Powerpoints buenísimos para estudiar)y Mariana (los jueves) y suelen dar muchos ejemplos de casos.Toman asistencia. Son 2 parciales escritos con casos a desarrollar (fundamentando con n el CCyCN y el manual de Rivera)
A6: 6872 | B6: CROVI-FISSORE | C6: MA-VI | D6: PRESENCIAL | E6: 08:30-10:00 | F6: BAJO | G6: MIXTO | H6: NO | I6: NO | J6: Recomendada. Toma solo lo dado en clase con parciales escritos a desarrollar -en algunos casos oral-. No toma asistencia ni trabajos prácticos. | K6: TECNICA
A7: 6871 | B7: CROVI-GRAFEUILLE | C7: LU-JU | D7: VIRTUAL | E7: 08:30-10:00 | F7: BAJO | G7: MULTIPLECHOICE | H7: NO | I7: NO | J7: Se sigue un cronograma durante la cursada y se ven fallos para ejemplificar los conceptos. Parciales hay uno solo con 25 preguntas MC que se promociona con 4. En caso de ir a recuperar, también promociona con 4. La mayoría aprueba y con buenas notas. | K7: TECNICA
A8: 6880 | B8: DE LORENZO-LAVALLE G. | C8: MA-VI | D8: PRESENCIAL | E8: 08:30-10:00 | F8: MEDIO | G8: MIXTO | H8: NO | J8: El profesor Lavalle explica de una manera dinámica y se le entiende muchísimo. No pasa lo mismo con otros docentes de la catedra, nunca explica el tema que le toca, se va por las ramas y termina hablando de otra cosa que no sirve. No toman asistencia nunca. Lo malo es que tardan muchísimo en pasar las notas de los parciales, para el primer parcial estuvieron 1 mes sin decirnos nuestra nota, también siempre llegan al menos 15 minutos tarde a la clase. El parcial se divide en 2 partes, la primera es multiple choice y si lo aprobas, pasas a la parte escrita, donde te suelen dejar usar el código civil.
A9: 6822 | B9: GARRIDO C.-BALMACEDA M. | C9: MA-VI | D9: PRESENCIAL | E9: 08:30-10:00 | F9: MEDIO | G9: MIXTO | H9: SI | I9: SI | J9: Las clases son entretenidas y dinámicas. Cada clase intercala entre dos profes para dictar la clase. No toman lista, ni mandan trabajos prácticos pero piden alguna que otra tarea en la primer parte de la materia. En los exámenes se toma teoría y práctica, son para redactar y multiple choice. El recuperatorio y el final son orales. | K9: TECNICA
A10: 6841 | B10: LAFERRIERE-ARCOS | C10: LU-JU | D10: PRESENCIAL | E10: 08:30-10:00 | F10: MEDIO | G10: ESCRITO | H10: NO | I10: SI | J10: La recomiendo, los lunes hace clases de consultas y los jueves se dan casos prácticos. Tiene todas las clases subidas a YouTube y el material es a elección se super entienden las clases, es promocionable y pro alumno. Los parciales son dos y escritos. | K10: TECNICA
A11: 6842 | B11: LAFERRIERE-MUÑIZ | C11: LU-JU | D11: PRESENCIAL | E11: 08:30-10:00 | F11: ALTO | G11: MIXTO | H11: SI | J11: Los profes explican bien y son bastante organizados. Evaluan con dos parciales que tienen una parte choice y otra desarrollar, son bastante específicos pero se aprueba.
A12: 6850 | B12: SANTARELLI-FORNARI M. | C12: MA-VI | D12: PRESENCIAL | E12: 08:30-10:00 | J12: Buenas opiniones entre estudiantes. Tomaban un tp por semana con cada tema visto, sirve mucho hacerlos para ir al día, no son pesados.
A13: 6801 | B13: BORDA-ZOTTO | C13: LU-JU | D13: PRESENCIAL | E13: 10:00-11:30 | F13: MEDIO | G13: ESCRITO | H13: NO | I13: NO | J13: Se aprende mucho de las clases, en las que se explican los casos que luego se toman en los parciales. A la hora de rendir, se hace con los apuntes y se eligen para contestar 2 de 5 preguntas. Se recomienda asistir a las clases. | K13: TECNICA
A14: 6802 | B14: BORDA-ZOTTO | C14: LU-JU | D14: PRESENCIAL | E14: 10:00-11:30 | F14: MEDIO | G14: ESCRITO | H14: NO | I14: NO | J14: Se aprende mucho de las clases, en las que se explican los casos que luego se toman en los parciales. A la hora de rendir, se hace con los apuntes y se eligen para contestar 2 de 5 preguntas. Se recomienda asistir a las clases. | K14: TECNICA
A15: 6860 | B15: BORDA-CAPRA | C15: LU-JU | D15: PRESENCIAL | E15: 10:00-11:30 | F15: MEDIO | G15: MIXTO | H15: SI | J15: Muy buena la recomiendo mucho. La profesora una genia, super dinámica la clase, fácil de seguir y divertida. Los parciales son exactamente lo que ella da en clase y deja a votación si hacer 2 o 3 para que sea más liviano y las fechas lo mismo, ella da opciones y se vota cual queda.
A16: 6881 | B16: DE LORENZO-LAVALLE G. | C16: MA-VI | D16: PRESENCIAL | E16: 10:00-11:30 | F16: MEDIO | G16: MIXTO | H16: NO | J16: El profesor Lavalle explica de una manera dinámica y se le entiende muchísimo. No pasa lo mismo con otros docentes de la catedra, nunca explica el tema que le toca, se va por las ramas y termina hablando de otra cosa que no sirve. No toman asistencia nunca. Lo malo es que tardan muchísimo en pasar las notas de los parciales, para el primer parcial estuvieron 1 mes sin decirnos nuestra nota, también siempre llegan al menos 15 minutos tarde a la clase. El parcial se divide en 2 partes, la primera es multiple choice y si lo aprobas, pasas a la parte escrita, donde te suelen dejar usar el código civil.
A17: 6823 | B17: GARRIDO C.-BALMACEDA M. | C17: MA-VI | D17: PRESENCIAL | E17: 10:00-11:30 | F17: MEDIO | G17: MIXTO | H17: SI | I17: SI | J17: Las clases son entretenidas y dinámicas. Cada clase intercala entre dos profes para dictar la clase. No toman lista, ni mandan trabajos prácticos pero piden alguna que otra tarea en la primer parte de la materia. En los exámenes se toma teoría y práctica, son para redactar y multiple choice. El recuperatorio y el final son orales. | K17: TECNICA
A18: 6828 | B18: GARRIDO C.-CARTA ADRIAN | C18: LU-JU | D18: PRESENCIAL | E18: 10:00-11:30 | F18: MEDIO | G18: ESCRITO | H18: NO | I18: NO | J18: Cátedra súper recomendable. El material de estudio es el mismo Código. El profesor es excelente explicando y da muchos ejemplos, muy predispuesto. Las preguntas de los parciales son específicas así que se contestan con precisión, y son muy fáciles si estudias. La gran mayoria aprueba y casi nadie fue a final.
A19: 6824 | B19: GARRIDO C.-CARTA ADRIAN | C19: MA-VI | D19: PRESENCIAL | E19: 10:00-11:30 | F19: MEDIO | G19: ESCRITO | H19: NO | I19: NO | J19: Cátedra súper recomendable. El material de estudio es el mismo Código. El profesor es excelente explicando y da muchos ejemplos, muy predispuesto. Las preguntas de los parciales son específicas así que se contestan con precisión, y son muy fáciles si estudias. La gran mayoria aprueba y casi nadie fue a final.
A20: 6845 | B20: LAFERRIERE-MAYOR L. | C20: LU-JU | D20: PRESENCIAL | E20: 10:00-11:30 | F20: ALTO | G20: MIXTO | H20: SI | J20: Explica las veces que sean necesarias sin problema y se manejan acorde a un cronograma para organiarse. Es necesario estudiar y se recomienda mantenerse al día con el material de estudio para facilitar la cursada. Los parciales son 5 preguntas choice y dos a desarrollar.
A21: 6846 | B21: LAFERRIERE-CRICI | C21: LU-JU | D21: PRESENCIAL | E21: 11:30-13:00 | F21: ALTO | G21: MIXTO | H21: SI | J21: Son bastante exigentes pero se aprende, buenos profes, mandan apuntes de las clases que sirven para estudiar. Los parciales son puntos choice a justificar y puntos a desarrollar y podes rendir un recuperatorio en caso de que te falte poquito para promocionar.
A22: 6803 | B22: PERALTA MARISCAL-LOVECE G. | C22: MA-VI | D22: VIRTUAL | E22: 10:00-11:30 | F22: ALTO | G22: ESCRITO | H22: NO | I22: NO | J22: Buena cátedra. Es remota, los parciales los toma de manera presencial, la única manera que verifican la regularidad es asistiendo a clases puntuales dictadas por el titular de cátedra | K22: TECNICA
A23: 6851 | B23: SANTARELLI-JAGOU | C23: MA-VI | D23: VIRTUAL | E23: 10:00-11:30
A24: 6804 | B24: PERALTA MARISCAL-SOBRINO A. | C24: MI | D24: PRESENCIAL | E24: 10:00-13:00 | F24: MEDIO | G24: MIXTO | H24: NO | I24: NO | J24: Los parciales son escritos y orales. No toman lista ni TPs. Usan manuales virtuales que suben al campus
A25: 6882 | B25: DE LORENZO-BERBERE D.J. | C25: LU-JU | D25: PRESENCIAL | E25: 11:30-13:00 | F25: MEDIO | G25: ESCRITO | H25: SI | I25: NO | J25: El docente explica bien pero es acelerado, tiene 2 ayudantes que dan 1 tema cada uno. El final es oral con el titular de cátedra. No tiene intensión de desaprobar estudiantes si quiere que aprendan y participen en clase, también hace que lxs Estudiantes expliquen 1 tema por grupo. | K25: APERTURA
A26: 6825 | B26: GARRIDO C.-RODRIGUEZ | C26: LU-JU | D26: PRESENCIAL | E26: 11:30-13:00 | F26: MEDIO | G26: ESCRITO | H26: SI | J26: Muy buena cátedra, los profesores se turnan para dar las clases, generalmente entre el Dr. Rodríguez y el Dr. Roberts, aunque hay dos ayudantes también, son muy apasionados en dar la materia y esto hace que entiendas, siempre están dispuestos a atender las dudas hasta que comprendas. Se manejan con el CCyC y un manual de dcho. civil que a mi me ayudó bastante para preparar la materia. Son re llevaderas las clases, y la anterior al examen es de repaso. Toman dos parciales con tres preguntas, las respuestas tienen que ser concisas, no es necesario desarrollar mucho. Si estudiaste lo aprobás seguro, la mayoría promocionó.
A27: 6826 | B27: GARRIDO C.-RODRIGUEZ | C27: LU-JU | D27: PRESENCIAL | E27: 11:30-13:00 | F27: MEDIO | G27: ESCRITO | H27: SI | J27: Muy buena cátedra, los profesores se turnan para dar las clases, generalmente entre el Dr. Rodríguez y el Dr. Roberts, aunque hay dos ayudantes también, son muy apasionados en dar la materia y esto hace que entiendas, siempre están dispuestos a atender las dudas hasta que comprendas. Se manejan con el CCyC y un manual de dcho. civil que a mi me ayudó bastante para preparar la materia. Son re llevaderas las clases, y la anterior al examen es de repaso. Toman dos parciales con tres preguntas, las respuestas tienen que ser concisas, no es necesario desarrollar mucho. Si estudiaste lo aprobás seguro, la mayoría promocionó.
A28: 6805 | B28: PERALTA MARISCAL-MORENO | C28: LU-JU | D28: PRESENCIAL | E28: 11:30-13:00 | F28: MEDIO | G28: ESCRITO | H28: SI | J28: No son exigentes, usan el manual de Lovece y evaluan con dos parciales escritos a desarrollar.
A29: 6873 | B29: CROVI-REVIRIEGO N. | C29: LU-JU | D29: PRESENCIAL | E29: 14:00-15:30 | F29: ALTO | G29: MIXTO | H29: SI | I29: NO | J29: 1er Parcial y el 2do escrito, MUY BUEN TRATO DOCENTE, ES ACCESIBLE ES MUY ATENTO AL GRUPO DE WPP Y TIENE VIDEOS DE YOUTUBE
A30: 6883 | B30: DE LORENZO-FELDMAN | C30: MA-VI | D30: PRESENCIAL | E30: 14:00-15:30 | F30: ALTO | I30: SI | J30: Muy exigente, malos comentarios del equipo docente. Mandan muchos tps e investigaciones.
A31: 6827 | B31: GARRIDO C.-MONTALTO A. | C31: LU-JU | D31: PRESENCIAL | E31: 14:00-15:30 | F31: MEDIO | H31: SI | J31: Totalmente recomendable, excelente cátedra, los ayudantes siempre bien dispuestos a responder todas las dudas que surjan, hay que llevarla al día con los artículos del CCyCN que se ven, es una materia "técnica", te toman sólo lo visto en clase, pero hay que conocer muy bien el contenido de los artículos vistos, no es rebuscada.
A32: 6843 | B32: LAFERRIERE-BENAVENTE | C32: LU-JU | D32: VIRTUAL | E32: 14:00-15:30 | F32: MEDIO | G32: ESCRITO | H32: NO | I32: SI | J32: Recomendada. Manual a elección y suben material a un drive. Además el titular tiene un canal de youtube que se pueden utilizar para estudiar. Buena predisposición docente. | K32: TECNICA
A33: 6829 | B33: GARRIDO C.-BRINSEK R. | C33: MI | D33: PRESENCIAL | E33: 14:00-17:00 | F33: ALTO | G33: MIXTO | H33: SI | J33: Es medio exigente pero son clases y contenidos super completos. Trabajamos todo en clase. Rosario es buenísima explicando. Igual, Guillermo (jtp) dio casi todas las clases, es bueno pero no como Rosario. 1er parcial oral (corrección exigente e injusta para algunos, otros con 9 e incompletos), 2° parcial oral bastante tranqui. Son pro alumnx. Rosario es lo más y nota si sabes o no. Clases con powerpoint. | K33: CONSERVADORA
A34: 6861 | B34: BORDA-CAPRA | C34: MA-VI | D34: PRESENCIAL | E34: 15:30-17:00 | F34: MEDIO | G34: MIXTO | H34: SI | J34: Muy buena la recomiendo mucho. La profesora una genia, super dinámica la clase, fácil de seguir y divertida. Los parciales son exactamente lo que ella da en clase y deja a votación si hacer 2 o 3 para que sea más liviano y las fechas lo mismo, ella da opciones y se vota cual queda.
A35: 6878 | B35: CROVI-FISSORE | C35: LU-JU | D35: PRESENCIAL | E35: 15:30-17:00 | F35: ALTO | G35: ESCRITO | H35: SI | I35: NO | J35: Es una comisión bastante exigente, para aprobar es necesario estar al día con las lecturas de la cursada y sobre todo con el manual. Evaluan tomando dos parciales, el primero es a desarollar y el segundo es oral. IMPORTANTE: En el primer cuatrimestre esta comisión no fue abierta por no llegar al mínimo de inscriptos que exige la Facultad.
A36: 6877 | B36: CROVI-GRAFEUILLE | C36: LU-JU | D36: PRESENCIAL | E36: 15:30-17:00 | F36: ALTO | G36: MIXTO | H36: SI | I36: NO | J36: Usan el manual de Rivera. Primer parcial escrito, tres preguntas, dos a desarrollar una especifica (definir un concepto) Segundo parcial oral, tres preguntas a desarrollar. Final oral. Importante seguir la lectura. Los profesores explican muy bien. | K36: TECNICA
A37: 6874 | B37: CROVI-PEREIRA V. | C37: LU-JU | D37: PRESENCIAL | E37: 15:30-17:00 | F37: ALTO | G37: ESCRITO | H37: SI | J37: Desde el primer día suben el cronograma de las clases, pero muchas veces no se respeta. También se carga a un classroom propio de la comisión material adicional como powerpoints y textos extras que ayudan bastante al momento de estudiar para los parciales. Los profes son super buena onda y clarísimos en la explicación, especialmente Nico y Mati que son quienes suelen dictar la materia. Para evaluar toman dos parciales escritos y cada uno cuenta con su recuperatorio. La cátedra es Pro-alumno pero no regalan nota. Es necesario leer y demostrar que adquiriste conocimiento. La cátedra la recomiendo, pero tampoco me pareció excelente. A pesar de que son super claros y que se encuentran a disposición de los alumnos, la organización, en cuanto al dictado de clases y el subir el material al aula virtual, no fue para nada buena. Si no te incomoda eso, la cátedra es buena, pero si pretendes mantener la lectura organizada por fechas y poder tener el material cargado todo de una quizá hayan mejores opciones
A38: 6875 | B38: CROVI-REVIRIEGO N. | C38: LU-JU | D38: PRESENCIAL | E38: 15:30-17:00 | F38: MEDIO | G38: ORAL | H38: SI | I38: NO | J38: Nivel de exigencia medio, "normal". Destacaron buena predisposición. // Son súper desorganizados, pasan la bibliografía por el grupo de wpp y tomaron el parcial un día que no se cursaba, terminaron súper tarde
A39: 6807 | B39: GARRIDO C.-AIZENBERG | C39: MA-VI | D39: PRESENCIAL | E39: 15:30-17:00 | F39: MEDIO | G39: ESCRITO | H39: SI | J39: El profesor Colla es un gran docente que explica de forma muy clara y quiere que aprendas. Te da una gran base de civil para el resto de las materias de esa rama. Dos parciales escritos con casos practicos, si seguis las clases y llevas la materia al dia es promocionable. Ponen notas altas. Muy bien organizadas y esquematizadas las clases, todo con cronograma. Recomiendo!!
A40: 6844 | B40: LAFERRIERE-BENAVENTE | C40: MA-VI | D40: VIRTUAL | E40: 15:30-17:00 | F40: MEDIO | J40: Recomendada. Manual a elección y suben material a un drive. Además el titular tiene un canal de youtube que se pueden utilizar para estudiar. Buena predisposición docente.
...

Sheet DDHH
A1: 📚 DERECHOS HUMANOS Y GARANTÍAS - 2º CUATRI 2026 - LA CÁMPORA 📚
A2: N° | B2: COMISIÓN | C2: DÍAS | D2: MODALIDAD | E2: HORARIO | F2: NIVEL | G2: PARCIAL | H2: TOMA LISTA | I2: TOMA TPS | J2: COMENTARIO | K2: POSTURA
A3: 6425 | B3: PIZZOLO-PAPA ANABEL | C3: LU-JU | D3: PRESENCIAL | E3: 07:00-08:30 | G3: ESCRITO | H3: SI | J3: Muy buena catedra, los dos profesores explican muy bien, primer parcial escrito y el segundo domiciliario. Toman todo lo visto en clase, no es necesario leer toda la bibliografia, sino las partes esenciales q ellos dicen. No toman asistencia en todas las clases pero si tenes q tener 2 o 3 para rendir cada parcial. Muy pro alumno, corrigen super rapido, la recomiendo mucho
A4: 6420 | B4: PIZZOLO-PAPA ANABEL | C4: LU-JU | D4: PRESENCIAL | E4: 07:00-08:30 | G4: ESCRITO | H4: SI | J4: Muy buena catedra, los dos profesores explican muy bien, primer parcial escrito y el segundo domiciliario. Toman todo lo visto en clase, no es necesario leer toda la bibliografia, sino las partes esenciales q ellos dicen. No toman asistencia en todas las clases pero si tenes q tener 2 o 3 para rendir cada parcial. Muy pro alumno, corrigen super rapido, la recomiendo mucho
A5: 6430 | B5: SABA-AIMAR | C5: LU-JU | D5: VIRTUAL | E5: 07:00-08:30 | F5: BAJO | G5: MIXTO | J5: Modalidad Evaluación: Cada alumno desarrolla un trabajo práctico escrito individual tipo monografía (pautas designadas al inicio) y un trabajo grupal que debe exponer en un coloquio. Bibliografía y Programa: Todo el material se envía en formato digital al inicio y durnte el curso su desarrollo
A6: 6450 | B6: TRAVIESO-LOGIOVINE YAMILA | C6: MA-VI | D6: PRESENCIAL | E6: 07:00-08:30 | F6: MEDIO | G6: MIXTO | H6: SI | I6: SI | J6: Los martes hay una profesora y los viernes otra, son super organizados y los ayudantes de cátedra ayudan mucho. Se trabaja con un manual de DDHH a elección, pero lo mejor es usar el de la cátedra. Ellos lo suben al campus y suman bibliografía que suma bastante. Hay pp que ayudan un montón a estudiar porque te dicen que no te puede faltar para estudiar. El primer parcial escrito, a desarrollar y un caso práctico bastante simple. Hay un punto que si o si tiene que estar bien hecho para aprobar el parcial. Si vas a clase seguro aprobas, hay que leer pero es clave tomar apuntes y prestar atención en las clases. El segundo parcial es oral. Elegís vos con qué tema empezar y después si te ven bien te hacen 1/2 preguntas de otros temas y nada más. Tiene 3 tps opcionales que no se promedian pero sirven para estudiar. Hay 1 tp obligatorio para resumir 2 fallos que se entrega por campus.
A7: 6451 | B7: TRAVIESO-LOGIOVINE YAMILA | C7: MA-VI | D7: PRESENCIAL | E7: 07:00-08:30 | F7: MEDIO | G7: MIXTO | H7: SI | I7: SI | J7: Los martes hay una profesora y los viernes otra, son super organizados y los ayudantes de cátedra ayudan mucho. Se trabaja con un manual de DDHH a elección, pero lo mejor es usar el de la cátedra. Ellos lo suben al campus y suman bibliografía que suma bastante. Hay pp que ayudan un montón a estudiar porque te dicen que no te puede faltar para estudiar. El primer parcial escrito, a desarrollar y un caso práctico bastante simple. Hay un punto que si o si tiene que estar bien hecho para aprobar el parcial. Si vas a clase seguro aprobas, hay que leer pero es clave tomar apuntes y prestar atención en las clases. El segundo parcial es oral. Elegís vos con qué tema empezar y después si te ven bien te hacen 1/2 preguntas de otros temas y nada más. Tiene 3 tps opcionales que no se promedian pero sirven para estudiar. Hay 1 tp obligatorio para resumir 2 fallos que se entrega por campus.
A8: 6470 | B8: ABRAMOVICH-VITOLO A. | C8: MA-VI | D8: PRESENCIAL | E8: 08:30-10:00 | F8: MEDIO | G8: ESCRITO | H8: NO | I8: SI | J8: NO TOMA PARCIAL - TRABAJO FINAL INTEGRADOR | K8: CONSERVADORA
A9: 6410 | B9: PINTO-FELGUERAS S. | C9: MA-VI | D9: PRESENCIAL | E9: 08:30-10:00 | H9: NO | J9: 2 parciales con 4/5 preguntas a desarrollar, te dejan usar bibliografia y apuntes( nada electronico) son casos practicos a resolver
A10: 6429 | B10: PIZZOLO-ROHR ALDANA | C10: LU-JU | D10: PRESENCIAL | E10: 08:30-10:00 | F10: MEDIO | G10: MIXTO | H10: NO | I10: SI | J10: La docente adjunta explica muy bien y tiene muchísimos ayudantes que explican los temas de la cursada, usa el manual de gonzales napolitano. el 1er parcial es de 4 preguntas escrito, y el 2do es domiciliario donde hay que explicar un derecho que se dio en clase y contestar preguntas además hay que adjuntar la legislación que contempla el derecho elegido | K10: APERTURA
A11: 6433 | B11: SABA- | C11: MA-VI | D11: PRESENCIAL | E11: 08:30-10:00 | F11: MEDIO | G11: ESCRITO | H11: SI | J11: Catedra recomendable. Te hacen pensar pero no es dificil. Aprendes.
A12: 6452 | B12: TRAVIESO-BALBI MELISA | C12: LU-JU | D12: PRESENCIAL | E12: 08:30-10:00 | F12: MEDIO | G12: ESCRITO | H12: SI | I12: SI | J12: Los profes son copados y hacen que las clases tengan buenas dinámicas. Los parciales son dos con preguntas a desarrollar, toman TPs que no son obligatorios. Mandan fallos, no usan manual. No son exigentes pero se aprende bastante
A13: 6416 | B13: PIZZOLO-ROHR ALDANA | C13: MI | D13: PRESENCIAL | E13: 08:30-11:30 | F13: MEDIO | G13: MIXTO | H13: NO | I13: SI | J13: La docente adjunta explica muy bien y tiene muchísimos ayudantes que explican los temas de la cursada, usa el manual de gonzales napolitano. el 1er parcial es de 4 preguntas escrito, y el 2do es domiciliario donde hay que explicar un derecho que se dio en clase y contestar preguntas además hay que adjuntar la legislación que contempla el derecho elegido | K13: APERTURA
A14: 6434 | B14: SABA-GIOSA L. | C14: MI | D14: PRESENCIAL | E14: 08:30-11:30 | F14: ALTO | G14: MIXTO | H14: NO | I14: NO | J14: un parcial escrito + domiciliario, manda controles de lectura todas las semanas. | K14: APERTURA
A15: 6453 | B15: TRAVIESO-GARCIA M. | C15: SA | D15: PRESENCIAL | E15: 08:30-11:30 | F15: BAJO | G15: MIXTO | H15: NO | I15: NO | J15: BIBLIO EN DRIVE Y MANUAL
A16: 6454 | B16: TRAVIESO-GARCIA M. | C16: SA | D16: PRESENCIAL | E16: 08:30-11:30 | F16: BAJO | G16: MIXTO | H16: NO | I16: NO | J16: BIBLIO EN DRIVE Y MANUAL
A17: 6476 | B17: ABRAMOVICH-GOMEZ LUCIA | C17: LU-JU | D17: PRESENCIAL | E17: 10:00-11:30 | F17: BAJO | G17: MIXTO | H17: NO | I17: NO | J17: Dos parciales de temas victos en clases, la profesora adjunta tiene buena llegada a los alumnos
A18: 6417 | B18: ABRAMOVICH-MORALES D. | C18: LU-JU | D18: PRESENCIAL | E18: 08:30-10:00 | J18: Comisión nueva
A19: 6411 | B19: ABRAMOVICH-MORALES D. | C19: LU-JU | D19: PRESENCIAL | E19: 10:00-11:30 | F19: ALTO | G19: MIXTO | H19: SI | I19: SI | J19: Toman parcial escrito y otro oral. buena llegada con los estudiantes. Cátedra para enriquecerse en materia de DDHH y Garantías. | K19: TECNICA
A20: 6436 | B20: SABA-ZALDUMBIDE | C20: MA-VI | D20: PRESENCIAL | E20: 10:00-11:30 | F20: MEDIO | G20: MIXTO | H20: SI | I20: SI | J20: Toman un examen inicial para orientar, seguido de un TP grupal y un final oral con posibilidad de recuperatorio. Su material esta en un MicrosoftTeam y con clases de apoyo.
A21: 6455 | B21: TRAVIESO-CURIEL | C21: LU-JU | D21: PRESENCIAL | E21: 14:00-15:30 | F21: MEDIO | G21: ESCRITO | H21: NO | I21: NO | J21: Recomendada por quienes la cursaron. Toma lo que da en clase, cursada amena. Pro alumno, no tienen problema en volver a explicar un tema y ponen notas altas. El examen puede incluir V/F, preguntas teóricas y casos prácticos. Profundiza cómo acceder al Sistema internacional de DDHH, se ve toda la parte procesal, y luego se profundiza en derechos específicos. Destacan su contenido de actualidad. | K21: TECNICA
A22: 6456 | B22: TRAVIESO-SANCHEZ MANCINI | C22: LU-JU | D22: PRESENCIAL | E22: 10:00-11:30 | F22: MEDIO | G22: ESCRITO | H22: SI | I22: SI | J22: Cátedra ordenada, siguen el cronograma, los profes son copados y explican bien, se sube la bibliografía al campus. No tienen ánimos de bochar a nadie, con los apuntes de clase y complementando un poco con la bibliografía se aprueba.
A23: 6471 | B23: ABRAMOVICH-G.NAPOLITANO | C23: LU-JU | D23: VIRTUAL | E23: 11:30-13:00 | F23: MEDIO | G23: MULTIPLECHOICE | H23: NO | I23: SI | J23: Gran comisión para los que queremos seguir derecho internacional público. Las profesoras explican bien y no tienen problema en contestar preguntas, hay un grupo de Whatsapp con los ayudantes para la dudas. Los parciales son por Forms mediante multiplechoice, durante la cursada mandaron TPs para la regularidad
A24: 6412 | B24: PINTO-SALGADO A. | C24: LU-JU | D24: PRESENCIAL | E24: 11:30-13:00 | G24: MULTIPLECHOICE | H24: SI | I24: SI, NO | J24: 2 Parciales verdadero y falso sin justificar, la bibliografia la suben a facebook los docentes
A25: 6458 | B25: TRAVIESO-CURIEL | C25: LU-JU | D25: PRESENCIAL | E25: 15:30-17:00 | F25: MEDIO | G25: ESCRITO | H25: NO | I25: NO | J25: Recomendada por quienes la cursaron. Toma lo que da en clase, cursada amena. Pro alumno, no tienen problema en volver a explicar un tema y ponen notas altas. El examen puede incluir V/F, preguntas teóricas y casos prácticos. Profundiza cómo acceder al Sistema internacional de DDHH, se ve toda la parte procesal, y luego se profundiza en derechos específicos. Destacan su contenido de actualidad. | K25: TECNICA
A26: 6457 | B26: TRAVIESO-MEIS M. | C26: LU-JU | D26: PRESENCIAL | E26: 11:30-13:00 | F26: BAJO | G26: MIXTO | H26: NO | I26: SI | J26: Explican bien y no tiene problema en poner notas altas. El primer parcial es domiciliario y el segundo oral en el que sirve mucho el concepto que tengan de vos por la participación en clase. // Son desorganizados, a veces faltan a las clases sin avisar. No tienen buena llegada con los estudiantes, no recomendada.
A27: 6403 | B27: PIZZOLO-RIERA | C27: MA-VI | D27: PRESENCIAL | E27: 11:30-13:30 | F27: MEDIO | G27: MIXTO | H27: SI | I27: SI | J27: Toman el primer parcial de forma escrita y el segundo oral. Toman TPs para la regularidad y nota. Son responsables con el cronograma
A28: 6472 | B28: ABRAMOVICH-G.NAPOLITANO | C28: LU-JU | D28: VIRTUAL | E28: 13:00:14:30 | F28: MEDIO | G28: MULTIPLECHOICE | H28: NO | I28: SI | J28: Gran comisión para los que queremos seguir derecho internacional público. Las profesoras explican bien y no tienen problema en contestar preguntas, hay un grupo de Whatsapp con los ayudantes para la dudas. Los parciales son por Forms mediante multiplechoice, durante la cursada mandaron TPs para la regularidad
A29: 6437 | B29: SABA-PEREZ ANDREA | C29: LU-JU | D29: PRESENCIAL | E29: 14:00-15:30 | F29: MEDIO | G29: MIXTO | H29: SI | I29: SI | J29: Los parciales varian entre multiple choice y preguntas a desarrollar, corrige de forma global.Toma asistencia, se promociona con 6
A30: 6438 | B30: SABA-LOIANNO ADELINA | C30: MI | D30: PRESENCIAL | E30: 14:00-17:00 | F30: ALTO | G30: ESCRITO | H30: SI | I30: SI | J30: Dos parciales escrito, llegada al alumno. tp como regularidad, no siempre toma asistencia | K30: TECNICA
A31: 6473 | B31: A DESIGNAR - AGUIRRE L. | C31: LU-JU | D31: PRESENCIAL | E31: 15:30-17:00 | F31: BAJO | G31: ESCRITO | H31: NO | I31: SI | J31: La profesora Aguirre tiene buena llegada con los alumnos, toma dos parciales como TPs a entregar con tiempo y un final integrador
A32: 6421 | B32: PIZZOLO-PAVIONI NATALÍ | C32: MA-VI | D32: PRESENCIAL | E32: 15:30-17:00 | F32: MEDIO | G32: ESCRITO | H32: NO | I32: NO | J32: Parciales escritos(preguntas a desarrollar, verdaderos y falsos a justificar). El recuperatorio y el final son orales. Contenido del primer parcial , la mayoría pudo haber sido visto en el cbc. En el segundo parcial, se complementan todos los temas con fallos. Los profesores explican muy bien. RECOMENDADA. | K32: APERTURA
A33: 6422 | B33: PIZZOLO-RIERA | C33: MA-VI | D33: PRESENCIAL | E33: 15:30-17:00 | F33: MEDIO | G33: MIXTO | H33: SI | I33: SI | J33: Muy buen equipo docente, recomiendo. Primer parcial escrito, segundo simulacro de juicio. Se aprende mucho.
A34: 6459 | B34: TRAVIESO-G.STIER | C34: MA-VI | D34: PRESENCIAL | E34: 15:30-17:00 | F34: MEDIO | G34: MIXTO | H34: SI | I34: NO | J34: Muy recomendada. Cátedra proalumno y con ánimos de que aprendas participando e involucrándose. Tienen muy buen trato lo que hace muy amena la cursada, muy recomendada si estás arrancando en la Facultad. Toman parciales domiciliarios, escritos y orales que se pueden responder con las guías y lo dado en clase. 3 instancias de evaluación, la primera es un tp domiciliario, la segunda es un escrito presencial, y la tercera es un oral. También se arman clases de debate que suman | K34: APERTURA
A35: 6413 | B35: PINTO-FILIPPINI | C35: MI | D35: PRESENCIAL | E35: 15:30-18:30 | F35: ALTO | G35: MIXTO | H35: NO | I35: SI | J35: Se recomienda quienes les guste la materia y se quieran especializar en la materia. Se aprende mucho pero hay que estudiar y muy importante seguirle el ritmo.
A36: 6415 | B36: PINTO-SIGAL | C36: MI | D36: PRESENCIAL | E36: 15:30-18:30
A37: 6474 | B37: ABRAMOVICH-REVIRIEGO | C37: LU-JU | D37: PRESENCIAL | E37: 17:00-18:30 | F37: ALTO | G37: MIXTO | H37: SI | I37: NO | J37: Varían entre parciales multiplechoice y a desarrollar. Si bien siguen el cronograma pueden ser desorganizados con las clases
A38: 6423 | B38: PIZZOLO-PAVIONI NATALÍ | C38: MA-VI | D38: PRESENCIAL | E38: 17:00-18:30 | F38: MEDIO | G38: ESCRITO | H38: NO | I38: NO | J38: Parciales escritos(preguntas a desarrollar, verdaderos y falsos a justificar). El recuperatorio y el final son orales. Contenido del primer parcial , la mayoría pudo haber sido visto en el cbc. En el segundo parcial, se complementan todos los temas con fallos. Los profesores explican muy bien. RECOMENDADA. | K38: APERTURA
A39: 6424 | B39: PIZZOLO-ZIMERMAN S | C39: MA-VI | D39: PRESENCIAL | E39: 17:00-18:30 | F39: ALTO | G39: MIXTO | H39: SI | I39: SI | J39: tres parciales; dos escritos y uno oral. Cátedra super recomendable, comunmente visita a la EX-ESMA; hacen simulacro de la Corte IDH. | K39: APERTURA
A40: 6440 | B40: SABA-FERREIRA | C40: MA-VI | D40: PRESENCIAL | E40: 17:00-18:30 | F40: BAJO | G40: ESCRITO | H40: SI | J40: Buenas clases en las tematicas de genero, dos parciales sobre la identificacion de problematicas vistas en clases, a travez de casos.
...

Sheet ANÁLISIS 
A1: 📚 ANÁLISIS ECONÓMICO Y FINANCIERO - 2º CUATRI 2026 - LA CÁMPORA 📚
A2: N° | B2: COMISIÓN | C2: DÍAS | D2: MODALIDAD | E2: HORARIO | F2: NIVEL | G2: PARCIAL | H2: TOMA LISTA | I2: TOMA TPS | J2: COMENTARIO | K2: CORTE 1° CUATRI | L2: POSTURA
A3: 8659 | B3: DI PELINO-BARREÑA M. | C3: MI | D3: PRESENCIAL | E3: 10:00-13:00 | F3: MEDIO | G3: MIXTO | H3: SI | I3: SI | J3: No tienen ánimos de desaprobar, explican bien y se hacen dinámicas las clases. Toman dos parciales escritos y orales con TPs para subir nota | K3: =VLOOKUP(A3,CORTE!$A$2:$B$1045,2,0)
A4: 8620 | B4: MAZZA-HOFMANN | C4: MA-VI | D4: PRESENCIAL | E4: 07:00-08:30 | F4: BAJO | G4: ESCRITO | H4: SI | I4: NO | J4: Buenas cátedra, dos parciales escritos de verdadero o falsos justificar en una sola oración. | K4: =VLOOKUP(A4,CORTE!$A$2:$B$1045,2,0) | L4: TECNICA
A5: 8610 | B5: STORDEUR-BIDART MARINA | C5: LU-JU | D5: PRESENCIAL | E5: 07:00-08:30 | F5: MEDIO | G5: MIXTO | H5: NO | I5: NO | J5: Usan el manual de Mankiew, toman lo visto en clase que es lo mismo que leer las filminas que mandan. Los parciales son mitad multiplechoice y mitad escrito a desarrollar de casos prácticos | K5: =VLOOKUP(A5,CORTE!$A$2:$B$1045,2,0)
